/Users/bryanacton/Documents/GitHub/lead-measure/leadmeasure_env/lib/python3.9/site-packages/urllib3/__init__.py:35: NotOpenSSLWarning: urllib3 v2 only supports OpenSSL 1.1.1+, currently the 'ssl' module is compiled with 'LibreSSL 2.8.3'. See: https://github.com/urllib3/urllib3/issues/3020
  warnings.warn(
Traceback (most recent call last):
  File "/Users/bryanacton/Documents/GitHub/lead-measure/leadmeasure_env/lib/python3.9/site-packages/transformers/utils/import_utils.py", line 1967, in _get_module
    return importlib.import_module("." + module_name, self.__name__)
  File "/Library/Developer/CommandLineTools/Library/Frameworks/Python3.framework/Versions/3.9/lib/python3.9/importlib/__init__.py", line 127, in import_module
    return _bootstrap._gcd_import(name[level:], package, level)
  File "<frozen importlib._bootstrap>", line 1030, in _gcd_import
  File "<frozen importlib._bootstrap>", line 1007, in _find_and_load
  File "<frozen importlib._bootstrap>", line 972, in _find_and_load_unlocked
  File "<frozen importlib._bootstrap>", line 228, in _call_with_frames_removed
  File "<frozen importlib._bootstrap>", line 1030, in _gcd_import
  File "<frozen importlib._bootstrap>", line 1007, in _find_and_load
  File "<frozen importlib._bootstrap>", line 986, in _find_and_load_unlocked
  File "<frozen importlib._bootstrap>", line 680, in _load_unlocked
  File "<frozen importlib._bootstrap_external>", line 850, in exec_module
  File "<frozen importlib._bootstrap>", line 228, in _call_with_frames_removed
  File "/Users/bryanacton/Documents/GitHub/lead-measure/leadmeasure_env/lib/python3.9/site-packages/transformers/models/__init__.py", line 15, in <module>
    from . import (
  File "/Users/bryanacton/Documents/GitHub/lead-measure/leadmeasure_env/lib/python3.9/site-packages/transformers/models/dpr/__init__.py", line 30, in <module>
    sys.modules[__name__] = _LazyModule(__name__, _file, define_import_structure(_file), module_spec=__spec__)
  File "/Users/bryanacton/Documents/GitHub/lead-measure/leadmeasure_env/lib/python3.9/site-packages/transformers/utils/import_utils.py", line 2391, in define_import_structure
    import_structure = create_import_structure_from_path(module_path)
  File "/Users/bryanacton/Documents/GitHub/lead-measure/leadmeasure_env/lib/python3.9/site-packages/transformers/utils/import_utils.py", line 2162, in create_import_structure_from_path
    file_content = f.read()
OSError: [Errno 89] Operation canceled

The above exception was the direct cause of the following exception:

Traceback (most recent call last):
  File "/Users/bryanacton/Documents/GitHub/lead-measure/scripts/debug_train.py", line 8, in <module>
    from sentence_transformers import SentenceTransformer, models
  File "/Users/bryanacton/Documents/GitHub/lead-measure/leadmeasure_env/lib/python3.9/site-packages/sentence_transformers/__init__.py", line 14, in <module>
    from sentence_transformers.cross_encoder import (
  File "/Users/bryanacton/Documents/GitHub/lead-measure/leadmeasure_env/lib/python3.9/site-packages/sentence_transformers/cross_encoder/__init__.py", line 3, in <module>
    from .CrossEncoder import CrossEncoder
  File "/Users/bryanacton/Documents/GitHub/lead-measure/leadmeasure_env/lib/python3.9/site-packages/sentence_transformers/cross_encoder/CrossEncoder.py", line 19, in <module>
    from transformers import (
  File "<frozen importlib._bootstrap>", line 1055, in _handle_fromlist
  File "/Users/bryanacton/Documents/GitHub/lead-measure/leadmeasure_env/lib/python3.9/site-packages/transformers/utils/import_utils.py", line 1955, in __getattr__
    module = self._get_module(self._class_to_module[name])
  File "/Users/bryanacton/Documents/GitHub/lead-measure/leadmeasure_env/lib/python3.9/site-packages/transformers/utils/import_utils.py", line 1969, in _get_module
    raise RuntimeError(
RuntimeError: Failed to import transformers.models.auto because of the following error (look up to see its traceback):
[Errno 89] Operation canceled
